2025-08-10 12:05:24,893 [DEBUG] Training run_id: c1bf31cfaab5495fbb8fd59c06a52f00
2025-08-10 12:05:24,894 [DEBUG] Using outputs directory: /home/dennis-grisham/D501_Project_1_NYC_Airbnb/outputs
2025-08-10 12:05:24,894 [DEBUG][WRITE] params.json written by train_random_forest/run.py at 2025-08-10T12:05:24.894666 to /home/dennis-grisham/D501_Project_1_NYC_Airbnb/outputs/params.json
2025-08-10 12:05:24,895 [DEBUG][WRITE] rf_config.json written by train_random_forest/run.py at 2025-08-10T12:05:24.895059 to /home/dennis-grisham/D501_Project_1_NYC_Airbnb/outputs/rf_config.json
2025-08-10 12:05:24,895 [DEBUG] Using training artifact: train_data.csv:latest
2025-08-10 12:05:25,547 [DEBUG] Local training file path: ./artifacts/train_data.csv:latest/train_data.csv
2025-08-10 12:05:25,572 Minimum price: 0, Maximum price: 999
2025-08-10 12:05:25,578 Preparing sklearn pipeline
2025-08-10 12:05:25,579 Fitting model...
Traceback (most recent call last):
  File "/home/dennis-grisham/miniconda3/envs/mlflow-d20df18b17b0c54747eba2677649d2bbc0879a75/lib/python3.10/site-packages/pandas/core/indexes/base.py", line 3790, in get_loc
    return self._engine.get_loc(casted_key)
  File "index.pyx", line 152, in pandas._libs.index.IndexEngine.get_loc
  File "index.pyx", line 181, in pandas._libs.index.IndexEngine.get_loc
  File "pandas/_libs/hashtable_class_helper.pxi", line 7080, in pandas._libs.hashtable.PyObjectHashTable.get_item
  File "pandas/_libs/hashtable_class_helper.pxi", line 7088, in pandas._libs.hashtable.PyObjectHashTable.get_item
KeyError: 'last_review'
The above exception was the direct cause of the following exception:
Traceback (most recent call last):
  File "/home/dennis-grisham/miniconda3/envs/mlflow-d20df18b17b0c54747eba2677649d2bbc0879a75/lib/python3.10/site-packages/sklearn/utils/_indexing.py", line 361, in _get_column_indices
    col_idx = all_columns.get_loc(col)
  File "/home/dennis-grisham/miniconda3/envs/mlflow-d20df18b17b0c54747eba2677649d2bbc0879a75/lib/python3.10/site-packages/pandas/core/indexes/base.py", line 3797, in get_loc
    raise KeyError(key) from err
KeyError: 'last_review'
The above exception was the direct cause of the following exception:
Traceback (most recent call last):
  File "/home/dennis-grisham/D501_Project_1_NYC_Airbnb/src/train_random_forest/run.py", line 187, in <module>
    go(args)
  File "/home/dennis-grisham/D501_Project_1_NYC_Airbnb/src/train_random_forest/run.py", line 82, in go
    sk_pipe.fit(X_train, y_train)
  File "/home/dennis-grisham/miniconda3/envs/mlflow-d20df18b17b0c54747eba2677649d2bbc0879a75/lib/python3.10/site-packages/sklearn/base.py", line 1473, in wrapper
    return fit_method(estimator, *args, **kwargs)
  File "/home/dennis-grisham/miniconda3/envs/mlflow-d20df18b17b0c54747eba2677649d2bbc0879a75/lib/python3.10/site-packages/sklearn/pipeline.py", line 469, in fit
    Xt = self._fit(X, y, routed_params)
  File "/home/dennis-grisham/miniconda3/envs/mlflow-d20df18b17b0c54747eba2677649d2bbc0879a75/lib/python3.10/site-packages/sklearn/pipeline.py", line 406, in _fit
    X, fitted_transformer = fit_transform_one_cached(
  File "/home/dennis-grisham/miniconda3/envs/mlflow-d20df18b17b0c54747eba2677649d2bbc0879a75/lib/python3.10/site-packages/joblib/memory.py", line 326, in __call__
    return self.func(*args, **kwargs)
  File "/home/dennis-grisham/miniconda3/envs/mlflow-d20df18b17b0c54747eba2677649d2bbc0879a75/lib/python3.10/site-packages/sklearn/pipeline.py", line 1310, in _fit_transform_one
    res = transformer.fit_transform(X, y, **params.get("fit_transform", {}))
  File "/home/dennis-grisham/miniconda3/envs/mlflow-d20df18b17b0c54747eba2677649d2bbc0879a75/lib/python3.10/site-packages/sklearn/utils/_set_output.py", line 316, in wrapped
    data_to_wrap = f(self, X, *args, **kwargs)
  File "/home/dennis-grisham/miniconda3/envs/mlflow-d20df18b17b0c54747eba2677649d2bbc0879a75/lib/python3.10/site-packages/sklearn/base.py", line 1473, in wrapper
    return fit_method(estimator, *args, **kwargs)
  File "/home/dennis-grisham/miniconda3/envs/mlflow-d20df18b17b0c54747eba2677649d2bbc0879a75/lib/python3.10/site-packages/sklearn/compose/_column_transformer.py", line 968, in fit_transform
    self._validate_column_callables(X)
  File "/home/dennis-grisham/miniconda3/envs/mlflow-d20df18b17b0c54747eba2677649d2bbc0879a75/lib/python3.10/site-packages/sklearn/compose/_column_transformer.py", line 536, in _validate_column_callables
    transformer_to_input_indices[name] = _get_column_indices(X, columns)
  File "/home/dennis-grisham/miniconda3/envs/mlflow-d20df18b17b0c54747eba2677649d2bbc0879a75/lib/python3.10/site-packages/sklearn/utils/_indexing.py", line 369, in _get_column_indices
    raise ValueError("A given column is not a column of the dataframe") from e
ValueError: A given column is not a column of the dataframe